<?xml version="1.0"?>
<robot xmlns:xacro="http://www.ros.org/wiki/xacro">
    <xacro:include filename= "inertias.xacro"/>

    <material name= "blue">
        <color rgba= "0.2 0.2 1 1"/>
    </material>

    <material name= "black">
        <color rgba= "0 0 0 1" />
    </material>

    <link name= "base_link"/>

    <link name= "chassis">
        <xacro:inertial_box mass="1.0" x="0.2" y="0.162" z="0.05">
            <origin xyz= "0.1 0 0.05" rpy="0 0 0" />
        </xacro:inertial_box>
        <visual>
            <origin xyz= "0.1 0 0.05"/>
            <geometry>
                <box size= "0.2 0.162 0.1" />
            </geometry>
            <material name= "blue"/>
        </visual>
        <collision>
            <origin xyz= "0.1 0 0.05"/>
            <geometry>
                <box size= "0.2 0.162 0.1" />
            </geometry>
            <material name= "blue"/>
        </collision>
    </link>

    <gazebo reference= "chassis">
        <material>Gazebo/Blue</material>
    </gazebo>

    <joint name= "chassis_joint" type= "fixed">
        <parent link= "base_link"/>
        <child link= "chassis"/>
        <origin xyz = "-0.05 0 0"/>
    </joint>

    <link name="right_wheel">
        <xacro:inertial_cylinder mass="0.1" length="0.019" radius="0.0215">
            <origin xyz= "0 0 0" rpy="0 0 0" />
        </xacro:inertial_cylinder>
        <visual>
            <origin xyz= "0 0 0"/>
            <geometry>
                <cylinder radius="0.0215" length="0.019"/>
            </geometry>
            <material name="black"/>
        </visual>
        <collision>
            <origin xyz= "0 0 0"/>
            <geometry>
                <cylinder radius="0.0215" length="0.019"/>
            </geometry>
            <material name="black"/>
        </collision>
    </link>

    <gazebo reference= "right_wheel">
        <material> Gazebo/Black </material>
    </gazebo>

    <joint name="right_wheel_joint" type="continuous">
        <parent link="base_link"/>
        <child link="right_wheel"/>
        <origin xyz="0.0 0.0917 0.0" rpy="-1.5708 0.0 0.0"/>
        <axis xyz="0 0 1"/>
    </joint>

    <link name="left_wheel">
        <xacro:inertial_cylinder mass="0.1" length="0.019" radius="0.0215">
            <origin xyz= "0 0 0" rpy="0 0 0" />
        </xacro:inertial_cylinder>
        <visual>
            <origin xyz= "0 0 0"/>
            <geometry>
                <cylinder radius="0.0215" length="0.019"/>
            </geometry>
            <material name="black"/>
        </visual>
        <collision>
            <origin xyz= "0 0 0"/>
            <geometry>
                <cylinder radius="0.0215" length="0.019"/>
            </geometry>
            <material name="black"/>
        </collision>
    </link>
    
    <gazebo reference= "left_wheel">
        <material> Gazebo/Black </material>
    </gazebo>

    <joint name="left_wheel_joint" type="continuous">
        <parent link="base_link"/>
        <child link="left_wheel"/>
        <origin xyz="0.0 -0.0917 0.0" rpy="-1.5708 0.0 0.0"/>
        <axis xyz="0 0 1"/>
    </joint>

    <link name="caster_wheel">
        <xacro:inertial_sphere mass="0.1" radius="0.0214">
            <origin xyz="0 0 0" rpy="0 0 0"/>
        </xacro:inertial_sphere>
        <visual>
            <origin xyz= "0 0 0"/>
            <geometry>
                <sphere radius="0.0214"/>
            </geometry>
            <material name="black"/>
        </visual>
        <collision>
            <origin xyz= "0 0 0"/>
            <geometry>
                <sphere radius="0.0214"/>
            </geometry>
            <material name="black"/>
        </collision>
    </link>

    <gazebo reference= "caster_wheel">
        <material>Gazebo/Black</material>
        <mu1 value= "0.001"/>
        <mu2 value= "0.001"/>
    </gazebo>

    <joint name="caster_wheel_joint" type="fixed">
        <parent link="base_link"/>
        <child link="caster_wheel"/>
        <origin xyz="0.1 0.0 0.0"/>
        <axis xyz="0 0 1"/>
    </joint>
</robot>
